Workbook

Sheet Dashboard
A1: KnockIQ — Path to $1M Annual Revenue
A2: Revenue model & calculator | Adjust blue cells to model your business
A4: INPUTS & ASSUMPTIONS (edit blue cells)
A5: Parameter | B5: Value | C5: Unit | D5: Notes
A6: Basic plan price | B6: 25 | C6: $ / rep / mo | D6: Minimum tier
A7: Premium plan price | B7: 50 | C7: $ / rep / mo | D7: Premium tier
A8: Basic plan customer mix | B8: 0.75 | C8: % | D8: 75% of customers on basic
A9: Premium plan customer mix | B9: =1-B8 -> 0.25 | C9: % | D9: Calculated (1 - basic mix)
A10: Avg door knockers / company | B10: 10 | C10: reps | D10: Avg reps per paying company
A11: Monthly churn rate | B11: 0.05 | C11: % | D11: % of customers lost each month
A12: Target ARR | B12: 1000000 | C12: $ | D12: Annual revenue goal
A13: Target months | B13: 24 | C13: months | D13: Timeline to reach goal
A14: Intern commission rate | B14: 0.2 | C14: % | D14: % of revenue paid to intern on his customers
A15: % of new customers from intern | B15: 0.5 | C15: % | D15: Attribution: what share of monthly new signups intern sources
A17: CALCULATED METRICS (auto)
A18: Blended price per rep / month | B18: =B6*B8 + B7*B9 -> 31.25 | C18: $ | D18: Weighted by plan mix
A19: Avg revenue per customer / mo | B19: =B18*B10 -> 312.5 | C19: $ | D19: Blended ARPA
A20: Avg revenue per customer / yr | B20: =B19*12 -> 3750 | C20: $ | D20: Annual ARPA
A21: Target MRR (monthly recurring) | B21: =B12/12 -> 83333.333 | C21: $ | D21: $1M ARR ÷ 12
A22: Customers needed at target | B22: =B21/B19 -> 266.66667 | C22: companies | D22: Paying companies needed
A23: Total door knockers needed | B23: =B22*B10 -> 2666.6667 | C23: reps | D23: Total reps on platform
A25: INTERN COMMISSION IMPACT @ MONTH 24 (Base Case)
A26: Gross ARR @ M24 (Base) | B26: ='Monthly Projection'!L28 -> 1461000 | C26: $ | D26: From Monthly Projection
A27: Intern's attributable ARR @ M24 | B27: ='Monthly Projection'!O28 -> 742500 | C27: $ | D27: ARR from intern-sourced customers
A28: Annualized commission run-rate @ M24 | B28: ='Monthly Projection'!P28*12 -> 148500 | C28: $ | D28: Annual commission to intern
A29: KnockIQ NET ARR @ M24 (after commission) | B29: ='Monthly Projection'!R28 -> 1312500 | C29: $ | D29: Net revenue after intern commission
A30: Cumulative commission paid (M1-M24) | B30: ='Monthly Projection'!Q31 -> 98562.5 | C30: $ | D30: Total $ paid to intern over 24 mo
A33: SCENARIO OUTCOMES @ MONTH 24 (Gross ARR)
A34: Scenario | B34: Customers | C34: MRR | D34: ARR | E34: % of $1M target
A35: Conservative | B35: =Scenarios!D29 -> 212 | C35: =Scenarios!E29 -> 66250 | D35: =Scenarios!F29 -> 795000 | E35: =D35/$B$12 -> 0.795
A36: Base case | B36: =Scenarios!I29 -> 390 | C36: =Scenarios!J29 -> 121875 | D36: =Scenarios!K29 -> 1462500 | E36: =D36/$B$12 -> 1.4625
A37: Aggressive | B37: =Scenarios!M29 -> 600 | C37: =Scenarios!N29 -> 187500 | D37: =Scenarios!O29 -> 2250000 | E37: =D37/$B$12 -> 2.25
A40: How to use this model
A41: 1. Edit blue cells in the INPUTS section to reflect pricing, mix, churn, and goal. Edit orange cells for intern commission settings.
A42: 2. Open 'Monthly Projection' to see the 24-month build for the Base case. Adjust the blue 'New Customers' column to change the ramp.
A43: 3. Open 'Scenarios' to compare Conservative / Base / Aggressive ramp curves side-by-side.
A44: 4. Open 'Calculator' to run sensitivity analysis on churn, pricing mix, avg reps, and target timeline.
A45: 5. The intern earns 20% on revenue from customers HE signs up. Adjust attribution % (B15) to model how much he sources.

Sheet Monthly Projection
A1: Monthly Projection — Base Case (24 months) | Gross + Net of Intern Commission
A2: Adjust 'New Customers' column (blue). Intern columns auto-calculate from Dashboard B14 (commission %) & B15 (attribution %).
A3: GROSS REVENUE BUILD | M3: INTERN COMMISSION TRACKING
A4: Month | B4: M# | C4: New Cust | D4: Churned | E4: Total Cust | F4: Basic Cust | G4: Prem Cust | H4: Total Reps | I4: Basic MRR | J4: Prem MRR | K4: Total MRR | L4: Gross ARR | M4: Intern New | N4: Intern Total Cust | O4: Intern Attr ARR | P4: Comm This Mo | Q4: Cum Commission | R4: KnockIQ Net ARR
A5: M1 | B5: 1 | C5: 3 | D5: 0 | E5: =C5-D5 -> 3 | F5: =ROUND(E5*Dashboard!$B$8,0) -> 2 | G5: =E5-F5 -> 1 | H5: =E5*Dashboard!$B$10 -> 30 | I5: =F5*Dashboard!$B$10*Dashboard!$B$6 -> 500 | J5: =G5*Dashboard!$B$10*Dashboard!$B$7 -> 500 | K5: =I5+J5 -> 1000 | L5: =K5*12 -> 12000 | M5: =ROUND(C5*Dashboard!$B$15,0) -> 2 | N5: =M5 -> 2 | O5: =N5*Dashboard!$B$19*12 -> 7500 | P5: =N5*Dashboard!$B$19*Dashboard!$B$14 -> 125 | Q5: =P5 -> 125 | R5: =L5-P5*12 -> 10500
A6: M2 | B6: 2 | C6: 3 | D6: =ROUND(E5*Dashboard!$B$11,0) -> 0 | E6: =E5+C6-D6 -> 6 | F6: =ROUND(E6*Dashboard!$B$8,0) -> 5 | G6: =E6-F6 -> 1 | H6: =E6*Dashboard!$B$10 -> 60 | I6: =F6*Dashboard!$B$10*Dashboard!$B$6 -> 1250 | J6: =G6*Dashboard!$B$10*Dashboard!$B$7 -> 500 | K6: =I6+J6 -> 1750 | L6: =K6*12 -> 21000 | M6: =ROUND(C6*Dashboard!$B$15,0) -> 2 | N6: =N5+M6-ROUND(N5*Dashboard!$B$11,0) -> 4 | O6: =N6*Dashboard!$B$19*12 -> 15000 | P6: =N6*Dashboard!$B$19*Dashboard!$B$14 -> 250 | Q6: =Q5+P6 -> 375 | R6: =L6-P6*12 -> 18000
A7: M3 | B7: 3 | C7: 3 | D7: =ROUND(E6*Dashboard!$B$11,0) -> 0 | E7: =E6+C7-D7 -> 9 | F7: =ROUND(E7*Dashboard!$B$8,0) -> 7 | G7: =E7-F7 -> 2 | H7: =E7*Dashboard!$B$10 -> 90 | I7: =F7*Dashboard!$B$10*Dashboard!$B$6 -> 1750 | J7: =G7*Dashboard!$B$10*Dashboard!$B$7 -> 1000 | K7: =I7+J7 -> 2750 | L7: =K7*12 -> 33000 | M7: =ROUND(C7*Dashboard!$B$15,0) -> 2 | N7: =N6+M7-ROUND(N6*Dashboard!$B$11,0) -> 6 | O7: =N7*Dashboard!$B$19*12 -> 22500 | P7: =N7*Dashboard!$B$19*Dashboard!$B$14 -> 375 | Q7: =Q6+P7 -> 750 | R7: =L7-P7*12 -> 28500
A8: M4 | B8: 4 | C8: 5 | D8: =ROUND(E7*Dashboard!$B$11,0) -> 0 | E8: =E7+C8-D8 -> 14 | F8: =ROUND(E8*Dashboard!$B$8,0) -> 11 | G8: =E8-F8 -> 3 | H8: =E8*Dashboard!$B$10 -> 140 | I8: =F8*Dashboard!$B$10*Dashboard!$B$6 -> 2750 | J8: =G8*Dashboard!$B$10*Dashboard!$B$7 -> 1500 | K8: =I8+J8 -> 4250 | L8: =K8*12 -> 51000 | M8: =ROUND(C8*Dashboard!$B$15,0) -> 3 | N8: =N7+M8-ROUND(N7*Dashboard!$B$11,0) -> 9 | O8: =N8*Dashboard!$B$19*12 -> 33750 | P8: =N8*Dashboard!$B$19*Dashboard!$B$14 -> 562.5 | Q8: =Q7+P8 -> 1312.5 | R8: =L8-P8*12 -> 44250
A9: M5 | B9: 5 | C9: 5 | D9: =ROUND(E8*Dashboard!$B$11,0) -> 1 | E9: =E8+C9-D9 -> 18 | F9: =ROUND(E9*Dashboard!$B$8,0) -> 14 | G9: =E9-F9 -> 4 | H9: =E9*Dashboard!$B$10 -> 180 | I9: =F9*Dashboard!$B$10*Dashboard!$B$6 -> 3500 | J9: =G9*Dashboard!$B$10*Dashboard!$B$7 -> 2000 | K9: =I9+J9 -> 5500 | L9: =K9*12 -> 66000 | M9: =ROUND(C9*Dashboard!$B$15,0) -> 3 | N9: =N8+M9-ROUND(N8*Dashboard!$B$11,0) -> 12 | O9: =N9*Dashboard!$B$19*12 -> 45000 | P9: =N9*Dashboard!$B$19*Dashboard!$B$14 -> 750 | Q9: =Q8+P9 -> 2062.5 | R9: =L9-P9*12 -> 57000
A10: M6 | B10: 6 | C10: 5 | D10: =ROUND(E9*Dashboard!$B$11,0) -> 1 | E10: =E9+C10-D10 -> 22 | F10: =ROUND(E10*Dashboard!$B$8,0) -> 17 | G10: =E10-F10 -> 5 | H10: =E10*Dashboard!$B$10 -> 220 | I10: =F10*Dashboard!$B$10*Dashboard!$B$6 -> 4250 | J10: =G10*Dashboard!$B$10*Dashboard!$B$7 -> 2500 | K10: =I10+J10 -> 6750 | L10: =K10*12 -> 81000 | M10: =ROUND(C10*Dashboard!$B$15,0) -> 3 | N10: =N9+M10-ROUND(N9*Dashboard!$B$11,0) -> 14 | O10: =N10*Dashboard!$B$19*12 -> 52500 | P10: =N10*Dashboard!$B$19*Dashboard!$B$14 -> 875 | Q10: =Q9+P10 -> 2937.5 | R10: =L10-P10*12 -> 70500
A11: M7 | B11: 7 | C11: 8 | D11: =ROUND(E10*Dashboard!$B$11,0) -> 1 | E11: =E10+C11-D11 -> 29 | F11: =ROUND(E11*Dashboard!$B$8,0) -> 22 | G11: =E11-F11 -> 7 | H11: =E11*Dashboard!$B$10 -> 290 | I11: =F11*Dashboard!$B$10*Dashboard!$B$6 -> 5500 | J11: =G11*Dashboard!$B$10*Dashboard!$B$7 -> 3500 | K11: =I11+J11 -> 9000 | L11: =K11*12 -> 108000 | M11: =ROUND(C11*Dashboard!$B$15,0) -> 4 | N11: =N10+M11-ROUND(N10*Dashboard!$B$11,0) -> 17 | O11: =N11*Dashboard!$B$19*12 -> 63750 | P11: =N11*Dashboard!$B$19*Dashboard!$B$14 -> 1062.5 | Q11: =Q10+P11 -> 4000 | R11: =L11-P11*12 -> 95250
A12: M8 | B12: 8 | C12: 9 | D12: =ROUND(E11*Dashboard!$B$11,0) -> 1 | E12: =E11+C12-D12 -> 37 | F12: =ROUND(E12*Dashboard!$B$8,0) -> 28 | G12: =E12-F12 -> 9 | H12: =E12*Dashboard!$B$10 -> 370 | I12: =F12*Dashboard!$B$10*Dashboard!$B$6 -> 7000 | J12: =G12*Dashboard!$B$10*Dashboard!$B$7 -> 4500 | K12: =I12+J12 -> 11500 | L12: =K12*12 -> 138000 | M12: =ROUND(C12*Dashboard!$B$15,0) -> 5 | N12: =N11+M12-ROUND(N11*Dashboard!$B$11,0) -> 21 | O12: =N12*Dashboard!$B$19*12 -> 78750 | P12: =N12*Dashboard!$B$19*Dashboard!$B$14 -> 1312.5 | Q12: =Q11+P12 -> 5312.5 | R12: =L12-P12*12 -> 122250
A13: M9 | B13: 9 | C13: 10 | D13: =ROUND(E12*Dashboard!$B$11,0) -> 2 | E13: =E12+C13-D13 -> 45 | F13: =ROUND(E13*Dashboard!$B$8,0) -> 34 | G13: =E13-F13 -> 11 | H13: =E13*Dashboard!$B$10 -> 450 | I13: =F13*Dashboard!$B$10*Dashboard!$B$6 -> 8500 | J13: =G13*Dashboard!$B$10*Dashboard!$B$7 -> 5500 | K13: =I13+J13 -> 14000 | L13: =K13*12 -> 168000 | M13: =ROUND(C13*Dashboard!$B$15,0) -> 5 | N13: =N12+M13-ROUND(N12*Dashboard!$B$11,0) -> 25 | O13: =N13*Dashboard!$B$19*12 -> 93750 | P13: =N13*Dashboard!$B$19*Dashboard!$B$14 -> 1562.5 | Q13: =Q12+P13 -> 6875 | R13: =L13-P13*12 -> 149250
A14: M10 | B14: 10 | C14: 12 | D14: =ROUND(E13*Dashboard!$B$11,0) -> 2 | E14: =E13+C14-D14 -> 55 | F14: =ROUND(E14*Dashboard!$B$8,0) -> 41 | G14: =E14-F14 -> 14 | H14: =E14*Dashboard!$B$10 -> 550 | I14: =F14*Dashboard!$B$10*Dashboard!$B$6 -> 10250 | J14: =G14*Dashboard!$B$10*Dashboard!$B$7 -> 7000 | K14: =I14+J14 -> 17250 | L14: =K14*12 -> 207000 | M14: =ROUND(C14*Dashboard!$B$15,0) -> 6 | N14: =N13+M14-ROUND(N13*Dashboard!$B$11,0) -> 30 | O14: =N14*Dashboard!$B$19*12 -> 112500 | P14: =N14*Dashboard!$B$19*Dashboard!$B$14 -> 1875 | Q14: =Q13+P14 -> 8750 | R14: =L14-P14*12 -> 184500
A15: M11 | B15: 11 | C15: 14 | D15: =ROUND(E14*Dashboard!$B$11,0) -> 3 | E15: =E14+C15-D15 -> 66 | F15: =ROUND(E15*Dashboard!$B$8,0) -> 50 | G15: =E15-F15 -> 16 | H15: =E15*Dashboard!$B$10 -> 660 | I15: =F15*Dashboard!$B$10*Dashboard!$B$6 -> 12500 | J15: =G15*Dashboard!$B$10*Dashboard!$B$7 -> 8000 | K15: =I15+J15 -> 20500 | L15: =K15*12 -> 246000 | M15: =ROUND(C15*Dashboard!$B$15,0) -> 7 | N15: =N14+M15-ROUND(N14*Dashboard!$B$11,0) -> 35 | O15: =N15*Dashboard!$B$19*12 -> 131250 | P15: =N15*Dashboard!$B$19*Dashboard!$B$14 -> 2187.5 | Q15: =Q14+P15 -> 10937.5 | R15: =L15-P15*12 -> 219750
A16: M12 | B16: 12 | C16: 16 | D16: =ROUND(E15*Dashboard!$B$11,0) -> 3 | E16: =E15+C16-D16 -> 79 | F16: =ROUND(E16*Dashboard!$B$8,0) -> 59 | G16: =E16-F16 -> 20 | H16: =E16*Dashboard!$B$10 -> 790 | I16: =F16*Dashboard!$B$10*Dashboard!$B$6 -> 14750 | J16: =G16*Dashboard!$B$10*Dashboard!$B$7 -> 10000 | K16: =I16+J16 -> 24750 | L16: =K16*12 -> 297000 | M16: =ROUND(C16*Dashboard!$B$15,0) -> 8 | N16: =N15+M16-ROUND(N15*Dashboard!$B$11,0) -> 41 | O16: =N16*Dashboard!$B$19*12 -> 153750 | P16: =N16*Dashboard!$B$19*Dashboard!$B$14 -> 2562.5 | Q16: =Q15+P16 -> 13500 | R16: =L16-P16*12 -> 266250
A17: M13 | B17: 13 | C17: 18 | D17: =ROUND(E16*Dashboard!$B$11,0) -> 4 | E17: =E16+C17-D17 -> 93 | F17: =ROUND(E17*Dashboard!$B$8,0) -> 70 | G17: =E17-F17 -> 23 | H17: =E17*Dashboard!$B$10 -> 930 | I17: =F17*Dashboard!$B$10*Dashboard!$B$6 -> 17500 | J17: =G17*Dashboard!$B$10*Dashboard!$B$7 -> 11500 | K17: =I17+J17 -> 29000 | L17: =K17*12 -> 348000 | M17: =ROUND(C17*Dashboard!$B$15,0) -> 9 | N17: =N16+M17-ROUND(N16*Dashboard!$B$11,0) -> 48 | O17: =N17*Dashboard!$B$19*12 -> 180000 | P17: =N17*Dashboard!$B$19*Dashboard!$B$14 -> 3000 | Q17: =Q16+P17 -> 16500 | R17: =L17-P17*12 -> 312000
... A28: M24 | B28: 24 | C28: 56 | D28: =ROUND(E27*Dashboard!$B$11,0) -> 18 | E28: =E27+C28-D28 -> 390 | F28: =ROUND(E28*Dashboard!$B$8,0) -> 293 | G28: =E28-F28 -> 97 | H28: =E28*Dashboard!$B$10 -> 3900 | I28: =F28*Dashboard!$B$10*Dashboard!$B$6 -> 73250 | J28: =G28*Dashboard!$B$10*Dashboard!$B$7 -> 48500 | K28: =I28+J28 -> 121750 | L28: =K28*12 -> 1461000 | M28: =ROUND(C28*Dashboard!$B$15,0) -> 28 | N28: =N27+M28-ROUND(N27*Dashboard!$B$11,0) -> 198 | O28: =N28*Dashboard!$B$19*12 -> 742500 | P28: =N28*Dashboard!$B$19*Dashboard!$B$14 -> 12375 | Q28: =Q27+P28 -> 98562.5 | R28: =L28-P28*12 -> 1312500
A29: TOTAL / END | C29: =SUM(C5:C28) -> 522 | D29: =SUM(D5:D28) -> 132 | E29: =E28 -> 390 | K29: =K28 -> 121750 | L29: =L28 -> 1461000 | M29: =SUM(M5:M28) -> 266 | N29: =N28 -> 198 | O29: =O28 -> 742500 | P29: =P28 -> 12375 | Q29: =Q28 -> 98562.5 | R29: =R28 -> 1312500
A30: % of $1M target | L30: =L28/Dashboard!$B$12 -> 1.461 | R30: =R28/Dashboard!$B$12 -> 1.3125
A31: Cumulative commission M1-M24 | Q31: =Q28 -> 98562.5

Sheet Scenarios
A1: Scenarios — Conservative vs. Base vs. Aggressive
A2: Each scenario uses the SAME pricing/churn from Dashboard but a different new-customer ramp. Edit blue cells to test.
C3: CONSERVATIVE | H3: BASE CASE | L3: AGGRESSIVE
A4: Month | B4: M# | C4: New | D4: Total Cust | E4: MRR | F4: ARR | G4: % Tgt | H4: New | I4: Total Cust | J4: MRR | K4: ARR | L4: New | M4: Total Cust | N4: MRR | O4: ARR
A5: M1 | B5: 1 | C5: 2 | D5: =C5 -> 2 | E5: =D5*Dashboard!$B$19 -> 625 | F5: =E5*12 -> 7500 | G5: =F5/Dashboard!$B$12 -> 0.0075 | H5: 3 | I5: =H5 -> 3 | J5: =I5*Dashboard!$B$19 -> 937.5 | K5: =J5*12 -> 11250 | L5: 5 | M5: =L5 -> 5 | N5: =M5*Dashboard!$B$19 -> 1562.5 | O5: =N5*12 -> 18750
A6: M2 | B6: 2 | C6: 2 | D6: =D5+C6-ROUND(D5*Dashboard!$B$11,0) -> 4 | E6: =D6*Dashboard!$B$19 -> 1250 | F6: =E6*12 -> 15000 | G6: =F6/Dashboard!$B$12 -> 0.015 | H6: 3 | I6: =I5+H6-ROUND(I5*Dashboard!$B$11,0) -> 6 | J6: =I6*Dashboard!$B$19 -> 1875 | K6: =J6*12 -> 22500 | L6: 6 | M6: =M5+L6-ROUND(M5*Dashboard!$B$11,0) -> 11 | N6: =M6*Dashboard!$B$19 -> 3437.5 | O6: =N6*12 -> 41250
A7: M3 | B7: 3 | C7: 2 | D7: =D6+C7-ROUND(D6*Dashboard!$B$11,0) -> 6 | E7: =D7*Dashboard!$B$19 -> 1875 | F7: =E7*12 -> 22500 | G7: =F7/Dashboard!$B$12 -> 0.0225 | H7: 3 | I7: =I6+H7-ROUND(I6*Dashboard!$B$11,0) -> 9 | J7: =I7*Dashboard!$B$19 -> 2812.5 | K7: =J7*12 -> 33750 | L7: 7 | M7: =M6+L7-ROUND(M6*Dashboard!$B$11,0) -> 17 | N7: =M7*Dashboard!$B$19 -> 5312.5 | O7: =N7*12 -> 63750
A8: M4 | B8: 4 | C8: 3 | D8: =D7+C8-ROUND(D7*Dashboard!$B$11,0) -> 9 | E8: =D8*Dashboard!$B$19 -> 2812.5 | F8: =E8*12 -> 33750 | G8: =F8/Dashboard!$B$12 -> 0.03375 | H8: 5 | I8: =I7+H8-ROUND(I7*Dashboard!$B$11,0) -> 14 | J8: =I8*Dashboard!$B$19 -> 4375 | K8: =J8*12 -> 52500 | L8: 10 | M8: =M7+L8-ROUND(M7*Dashboard!$B$11,0) -> 26 | N8: =M8*Dashboard!$B$19 -> 8125 | O8: =N8*12 -> 97500
A9: M5 | B9: 5 | C9: 3 | D9: =D8+C9-ROUND(D8*Dashboard!$B$11,0) -> 12 | E9: =D9*Dashboard!$B$19 -> 3750 | F9: =E9*12 -> 45000 | G9: =F9/Dashboard!$B$12 -> 0.045 | H9: 5 | I9: =I8+H9-ROUND(I8*Dashboard!$B$11,0) -> 18 | J9: =I9*Dashboard!$B$19 -> 5625 | K9: =J9*12 -> 67500 | L9: 11 | M9: =M8+L9-ROUND(M8*Dashboard!$B$11,0) -> 36 | N9: =M9*Dashboard!$B$19 -> 11250 | O9: =N9*12 -> 135000
A10: M6 | B10: 6 | C10: 3 | D10: =D9+C10-ROUND(D9*Dashboard!$B$11,0) -> 14 | E10: =D10*Dashboard!$B$19 -> 4375 | F10: =E10*12 -> 52500 | G10: =F10/Dashboard!$B$12 -> 0.0525 | H10: 5 | I10: =I9+H10-ROUND(I9*Dashboard!$B$11,0) -> 22 | J10: =I10*Dashboard!$B$19 -> 6875 | K10: =J10*12 -> 82500 | L10: 13 | M10: =M9+L10-ROUND(M9*Dashboard!$B$11,0) -> 47 | N10: =M10*Dashboard!$B$19 -> 14687.5 | O10: =N10*12 -> 176250
A11: M7 | B11: 7 | C11: 5 | D11: =D10+C11-ROUND(D10*Dashboard!$B$11,0) -> 18 | E11: =D11*Dashboard!$B$19 -> 5625 | F11: =E11*12 -> 67500 | G11: =F11/Dashboard!$B$12 -> 0.0675 | H11: 8 | I11: =I10+H11-ROUND(I10*Dashboard!$B$11,0) -> 29 | J11: =I11*Dashboard!$B$19 -> 9062.5 | K11: =J11*12 -> 108750 | L11: 16 | M11: =M10+L11-ROUND(M10*Dashboard!$B$11,0) -> 61 | N11: =M11*Dashboard!$B$19 -> 19062.5 | O11: =N11*12 -> 228750
A12: M8 | B12: 8 | C12: 5 | D12: =D11+C12-ROUND(D11*Dashboard!$B$11,0) -> 22 | E12: =D12*Dashboard!$B$19 -> 6875 | F12: =E12*12 -> 82500 | G12: =F12/Dashboard!$B$12 -> 0.0825 | H12: 9 | I12: =I11+H12-ROUND(I11*Dashboard!$B$11,0) -> 37 | J12: =I12*Dashboard!$B$19 -> 11562.5 | K12: =J12*12 -> 138750 | L12: 18 | M12: =M11+L12-ROUND(M11*Dashboard!$B$11,0) -> 76 | N12: =M12*Dashboard!$B$19 -> 23750 | O12: =N12*12 -> 285000
A13: M9 | B13: 9 | C13: 6 | D13: =D12+C13-ROUND(D12*Dashboard!$B$11,0) -> 27 | E13: =D13*Dashboard!$B$19 -> 8437.5 | F13: =E13*12 -> 101250 | G13: =F13/Dashboard!$B$12 -> 0.10125 | H13: 10 | I13: =I12+H13-ROUND(I12*Dashboard!$B$11,0) -> 45 | J13: =I13*Dashboard!$B$19 -> 14062.5 | K13: =J13*12 -> 168750 | L13: 20 | M13: =M12+L13-ROUND(M12*Dashboard!$B$11,0) -> 92 | N13: =M13*Dashboard!$B$19 -> 28750 | O13: =N13*12 -> 345000
A14: M10 | B14: 10 | C14: 7 | D14: =D13+C14-ROUND(D13*Dashboard!$B$11,0) -> 33 | E14: =D14*Dashboard!$B$19 -> 10312.5 | F14: =E14*12 -> 123750 | G14: =F14/Dashboard!$B$12 -> 0.12375 | H14: 12 | I14: =I13+H14-ROUND(I13*Dashboard!$B$11,0) -> 55 | J14: =I14*Dashboard!$B$19 -> 17187.5 | K14: =J14*12 -> 206250 | L14: 23 | M14: =M13+L14-ROUND(M13*Dashboard!$B$11,0) -> 110 | N14: =M14*Dashboard!$B$19 -> 34375 | O14: =N14*12 -> 412500
A15: M11 | B15: 11 | C15: 8 | D15: =D14+C15-ROUND(D14*Dashboard!$B$11,0) -> 39 | E15: =D15*Dashboard!$B$19 -> 12187.5 | F15: =E15*12 -> 146250 | G15: =F15/Dashboard!$B$12 -> 0.14625 | H15: 14 | I15: =I14+H15-ROUND(I14*Dashboard!$B$11,0) -> 66 | J15: =I15*Dashboard!$B$19 -> 20625 | K15: =J15*12 -> 247500 | L15: 26 | M15: =M14+L15-ROUND(M14*Dashboard!$B$11,0) -> 130 | N15: =M15*Dashboard!$B$19 -> 40625 | O15: =N15*12 -> 487500
A16: M12 | B16: 12 | C16: 9 | D16: =D15+C16-ROUND(D15*Dashboard!$B$11,0) -> 46 | E16: =D16*Dashboard!$B$19 -> 14375 | F16: =E16*12 -> 172500 | G16: =F16/Dashboard!$B$12 -> 0.1725 | H16: 16 | I16: =I15+H16-ROUND(I15*Dashboard!$B$11,0) -> 79 | J16: =I16*Dashboard!$B$19 -> 24687.5 | K16: =J16*12 -> 296250 | L16: 29 | M16: =M15+L16-ROUND(M15*Dashboard!$B$11,0) -> 152 | N16: =M16*Dashboard!$B$19 -> 47500 | O16: =N16*12 -> 570000
A17: M13 | B17: 13 | C17: 10 | D17: =D16+C17-ROUND(D16*Dashboard!$B$11,0) -> 54 | E17: =D17*Dashboard!$B$19 -> 16875 | F17: =E17*12 -> 202500 | G17: =F17/Dashboard!$B$12 -> 0.2025 | H17: 18 | I17: =I16+H17-ROUND(I16*Dashboard!$B$11,0) -> 93 | J17: =I17*Dashboard!$B$19 -> 29062.5 | K17: =J17*12 -> 348750 | L17: 32 | M17: =M16+L17-ROUND(M16*Dashboard!$B$11,0) -> 176 | N17: =M17*Dashboard!$B$19 -> 55000 | O17: =N17*12 -> 660000
... A28: M24 | B28: 24 | C28: 30 | D28: =D27+C28-ROUND(D27*Dashboard!$B$11,0) -> 212 | E28: =D28*Dashboard!$B$19 -> 66250 | F28: =E28*12 -> 795000 | G28: =F28/Dashboard!$B$12 -> 0.795 | H28: 56 | I28: =I27+H28-ROUND(I27*Dashboard!$B$11,0) -> 390 | J28: =I28*Dashboard!$B$19 -> 121875 | K28: =J28*12 -> 1462500 | L28: 76 | M28: =M27+L28-ROUND(M27*Dashboard!$B$11,0) -> 600 | N28: =M28*Dashboard!$B$19 -> 187500 | O28: =N28*12 -> 2250000
A29: @ M24 → | B29: 24 | C29: =C28 -> 30 | D29: =D28 -> 212 | E29: =E28 -> 66250 | F29: =F28 -> 795000 | G29: =G28 -> 0.795 | H29: =H28 -> 56 | I29: =I28 -> 390 | J29: =J28 -> 121875 | ... O29: =O28 -> 2250000
A32: Ramp design notes
A33: Conservative: Slow start (2/mo), reaches 30 net adds/mo by M24. Tests product-market fit with limited GTM spend.
A34: Base case: Calibrated to hit ~$1M ARR by M24 with 5% monthly churn. Assumes blended GTM: inbound + 1-2 AEs + paid ads + intern.
A35: Aggressive: Funded GTM with multiple AEs, heavier ad spend, and partnerships kicking in by M9.
A36: Note: Scenarios show GROSS ARR. Net of intern commission depends on attribution % (Dashboard B15) — see Monthly Projection tab.

Sheet Calculator
A1: Sensitivity Calculator — What does it take to hit $1M ARR?
A2: Each table varies ONE input while holding all others constant (from Dashboard).
A4: TABLE 1 — Vary Basic-vs-Premium Customer Mix
A5: Basic mix % | B5: Premium mix % | C5: Blended $/rep/mo | D5: ARPA/mo | E5: ARPA/year | F5: Customers needed | G5: Total reps needed | H5: vs Base
A6: 1 | B6: =1-A6 -> 0 | C6: =A6*Dashboard!$B$6+B6*Dashboard!$B$7 -> 25 | D6: =C6*Dashboard!$B$10 -> 250 | E6: =D6*12 -> 3000 | F6: =ROUNDUP(Dashboard!$B$12/E6,0) -> 334 | G6: =F6*Dashboard!$B$10 -> 3340 | H6: =F6/ROUNDUP(Dashboard!$B$12/Dashboard!$B$20,0)-1 -> 0.25093633
A7: 0.9 | B7: =1-A7 -> 0.1 | C7: =A7*Dashboard!$B$6+B7*Dashboard!$B$7 -> 27.5 | D7: =C7*Dashboard!$B$10 -> 275 | E7: =D7*12 -> 3300 | F7: =ROUNDUP(Dashboard!$B$12/E7,0) -> 304 | G7: =F7*Dashboard!$B$10 -> 3040 | H7: =F7/ROUNDUP(Dashboard!$B$12/Dashboard!$B$20,0)-1 -> 0.13857678
A8: 0.75 | B8: =1-A8 -> 0.25 | C8: =A8*Dashboard!$B$6+B8*Dashboard!$B$7 -> 31.25 | D8: =C8*Dashboard!$B$10 -> 312.5 | E8: =D8*12 -> 3750 | F8: =ROUNDUP(Dashboard!$B$12/E8,0) -> 267 | G8: =F8*Dashboard!$B$10 -> 2670 | H8: =F8/ROUNDUP(Dashboard!$B$12/Dashboard!$B$20,0)-1 -> 0
A9: 0.6 | B9: =1-A9 -> 0.4 | C9: =A9*Dashboard!$B$6+B9*Dashboard!$B$7 -> 35 | D9: =C9*Dashboard!$B$10 -> 350 | E9: =D9*12 -> 4200 | F9: =ROUNDUP(Dashboard!$B$12/E9,0) -> 239 | G9: =F9*Dashboard!$B$10 -> 2390 | H9: =F9/ROUNDUP(Dashboard!$B$12/Dashboard!$B$20,0)-1 -> -0.10486891
A10: 0.5 | B10: =1-A10 -> 0.5 | C10: =A10*Dashboard!$B$6+B10*Dashboard!$B$7 -> 37.5 | D10: =C10*Dashboard!$B$10 -> 375 | E10: =D10*12 -> 4500 | F10: =ROUNDUP(Dashboard!$B$12/E10,0) -> 223 | G10: =F10*Dashboard!$B$10 -> 2230 | H10: =F10/ROUNDUP(Dashboard!$B$12/Dashboard!$B$20,0)-1 -> -0.16479401
A11: 0.25 | B11: =1-A11 -> 0.75 | C11: =A11*Dashboard!$B$6+B11*Dashboard!$B$7 -> 43.75 | D11: =C11*Dashboard!$B$10 -> 437.5 | E11: =D11*12 -> 5250 | F11: =ROUNDUP(Dashboard!$B$12/E11,0) -> 191 | G11: =F11*Dashboard!$B$10 -> 1910 | H11: =F11/ROUNDUP(Dashboard!$B$12/Dashboard!$B$20,0)-1 -> -0.28464419
A12: 0 | B12: =1-A12 -> 1 | C12: =A12*Dashboard!$B$6+B12*Dashboard!$B$7 -> 50 | D12: =C12*Dashboard!$B$10 -> 500 | E12: =D12*12 -> 6000 | F12: =ROUNDUP(Dashboard!$B$12/E12,0) -> 167 | G12: =F12*Dashboard!$B$10 -> 1670 | H12: =F12/ROUNDUP(Dashboard!$B$12/Dashboard!$B$20,0)-1 -> -0.37453184
A14: TABLE 2 — Vary Avg Door Knockers per Customer
A15: Avg reps / customer | B15: Blended $/rep/mo | C15: ARPA/mo | D15: ARPA/year | E15: Customers needed | F15: Total reps needed | G15: MRR @ target | H15: ARR @ target
A16: 3 | B16: =Dashboard!$B$18 -> 31.25 | C16: =B16*A16 -> 93.75 | D16: =C16*12 -> 1125 | E16: =ROUNDUP(Dashboard!$B$12/D16,0) -> 889 | F16: =E16*A16 -> 2667 | G16: =E16*C16 -> 83343.75 | H16: =G16*12 -> 1000125
A17: 5 | B17: =Dashboard!$B$18 -> 31.25 | C17: =B17*A17 -> 156.25 | D17: =C17*12 -> 1875 | E17: =ROUNDUP(Dashboard!$B$12/D17,0) -> 534 | F17: =E17*A17 -> 2670 | G17: =E17*C17 -> 83437.5 | H17: =G17*12 -> 1001250
A18: 7 | B18: =Dashboard!$B$18 -> 31.25 | C18: =B18*A18 -> 218.75 | D18: =C18*12 -> 2625 | E18: =ROUNDUP(Dashboard!$B$12/D18,0) -> 381 | F18: =E18*A18 -> 2667 | G18: =E18*C18 -> 83343.75 | H18: =G18*12 -> 1000125
A19: 10 | B19: =Dashboard!$B$18 -> 31.25 | C19: =B19*A19 -> 312.5 | D19: =C19*12 -> 3750 | E19: =ROUNDUP(Dashboard!$B$12/D19,0) -> 267 | F19: =E19*A19 -> 2670 | G19: =E19*C19 -> 83437.5 | H19: =G19*12 -> 1001250
A20: 15 | B20: =Dashboard!$B$18 -> 31.25 | C20: =B20*A20 -> 468.75 | D20: =C20*12 -> 5625 | E20: =ROUNDUP(Dashboard!$B$12/D20,0) -> 178 | F20: =E20*A20 -> 2670 | G20: =E20*C20 -> 83437.5 | H20: =G20*12 -> 1001250
A21: 20 | B21: =Dashboard!$B$18 -> 31.25 | C21: =B21*A21 -> 625 | D21: =C21*12 -> 7500 | E21: =ROUNDUP(Dashboard!$B$12/D21,0) -> 134 | F21: =E21*A21 -> 2680 | G21: =E21*C21 -> 83750 | H21: =G21*12 -> 1005000
A22: 30 | B22: =Dashboard!$B$18 -> 31.25 | C22: =B22*A22 -> 937.5 | D22: =C22*12 -> 11250 | E22: =ROUNDUP(Dashboard!$B$12/D22,0) -> 89 | F22: =E22*A22 -> 2670 | G22: =E22*C22 -> 83437.5 | H22: =G22*12 -> 1001250
A25: TABLE 3 — Vary Monthly Churn Rate (impact on gross adds required at steady state)
A26: Monthly churn | B26: Annual churn (approx) | C26: Customers @ $1M ARR | D26: Monthly churned @ target | E26: Gross adds / mo needed | F26: Gross adds / yr | G26: Avg cust life (mo) | H26: LTV per customer
A27: 0.01 | B27: =1-(1-A27)^12 -> 0.11361513 | C27: =ROUNDUP(Dashboard!$B$12/Dashboard!$B$20,0) -> 267 | D27: =ROUND(C27*A27,0) -> 3 | E27: =D27 -> 3 | F27: =E27*12 -> 36 | G27: =1/A27 -> 100 | H27: =G27*Dashboard!$B$19 -> 31250
A28: 0.02 | B28: =1-(1-A28)^12 -> 0.21528328 | C28: =ROUNDUP(Dashboard!$B$12/Dashboard!$B$20,0) -> 267 | D28: =ROUND(C28*A28,0) -> 5 | E28: =D28 -> 5 | F28: =E28*12 -> 60 | G28: =1/A28 -> 50 | H28: =G28*Dashboard!$B$19 -> 15625
A29: 0.03 | B29: =1-(1-A29)^12 -> 0.30615764 | C29: =ROUNDUP(Dashboard!$B$12/Dashboard!$B$20,0) -> 267 | D29: =ROUND(C29*A29,0) -> 8 | E29: =D29 -> 8 | F29: =E29*12 -> 96 | G29: =1/A29 -> 33.333333 | H29: =G29*Dashboard!$B$19 -> 10416.667
A30: 0.05 | B30: =1-(1-A30)^12 -> 0.45963991 | C30: =ROUNDUP(Dashboard!$B$12/Dashboard!$B$20,0) -> 267 | D30: =ROUND(C30*A30,0) -> 13 | E30: =D30 -> 13 | F30: =E30*12 -> 156 | G30: =1/A30 -> 20 | H30: =G30*Dashboard!$B$19 -> 6250
A31: 0.07 | B31: =1-(1-A31)^12 -> 0.5814037 | C31: =ROUNDUP(Dashboard!$B$12/Dashboard!$B$20,0) -> 267 | D31: =ROUND(C31*A31,0) -> 19 | E31: =D31 -> 19 | F31: =E31*12 -> 228 | G31: =1/A31 -> 14.285714 | H31: =G31*Dashboard!$B$19 -> 4464.2857
A32: 0.1 | B32: =1-(1-A32)^12 -> 0.71757046 | C32: =ROUNDUP(Dashboard!$B$12/Dashboard!$B$20,0) -> 267 | D32: =ROUND(C32*A32,0) -> 27 | E32: =D32 -> 27 | F32: =E32*12 -> 324 | G32: =1/A32 -> 10 | H32: =G32*Dashboard!$B$19 -> 3125
A35: TABLE 4 — Avg Monthly Adds Required to Hit $1M ARR by Target Month
A36: Months to target | B36: Churn (from Dash) | C36: Customers needed | D36: Avg monthly net adds | E36: Approx gross adds/mo | F36: Approx gross adds/yr | G36: Reality check
A37: 12 | B37: =Dashboard!$B$11 -> 0.05 | C37: =ROUNDUP(Dashboard!$B$12/Dashboard!$B$20,0) -> 267 | D37: =ROUNDUP(C37/A37,1) -> 22.3 | E37: =ROUNDUP(D37+(C37/2)*B37,1) -> 29 | F37: =E37*12 -> 348 | G37: =IF(E37<10,"Very feasible",IF(E37<25,"Realistic w/ GTM",IF(E37<50,"Aggressive - need funded sales","Requires major capital"))) -> Aggressive - need funded sales
A38: 18 | B38: =Dashboard!$B$11 -> 0.05 | C38: =ROUNDUP(Dashboard!$B$12/Dashboard!$B$20,0) -> 267 | D38: =ROUNDUP(C38/A38,1) -> 14.9 | E38: =ROUNDUP(D38+(C38/2)*B38,1) -> 21.6 | F38: =E38*12 -> 259.2 | G38: =IF(E38<10,"Very feasible",IF(E38<25,"Realistic w/ GTM",IF(E38<50,"Aggressive - need funded sales","Requires major capital"))) -> Realistic w/ GTM
A39: 24 | B39: =Dashboard!$B$11 -> 0.05 | C39: =ROUNDUP(Dashboard!$B$12/Dashboard!$B$20,0) -> 267 | D39: =ROUNDUP(C39/A39,1) -> 11.2 | E39: =ROUNDUP(D39+(C39/2)*B39,1) -> 17.9 | F39: =E39*12 -> 214.8 | G39: =IF(E39<10,"Very feasible",IF(E39<25,"Realistic w/ GTM",IF(E39<50,"Aggressive - need funded sales","Requires major capital"))) -> Realistic w/ GTM
A40: 30 | B40: =Dashboard!$B$11 -> 0.05 | C40: =ROUNDUP(Dashboard!$B$12/Dashboard!$B$20,0) -> 267 | D40: =ROUNDUP(C40/A40,1) -> 8.9 | E40: =ROUNDUP(D40+(C40/2)*B40,1) -> 15.6 | F40: =E40*12 -> 187.2 | G40: =IF(E40<10,"Very feasible",IF(E40<25,"Realistic w/ GTM",IF(E40<50,"Aggressive - need funded sales","Requires major capital"))) -> Realistic w/ GTM
A41: 36 | B41: =Dashboard!$B$11 -> 0.05 | C41: =ROUNDUP(Dashboard!$B$12/Dashboard!$B$20,0) -> 267 | D41: =ROUNDUP(C41/A41,1) -> 7.5 | E41: =ROUNDUP(D41+(C41/2)*B41,1) -> 14.2 | F41: =E41*12 -> 170.4 | G41: =IF(E41<10,"Very feasible",IF(E41<25,"Realistic w/ GTM",IF(E41<50,"Aggressive - need funded sales","Requires major capital"))) -> Realistic w/ GTM
A44: TABLE 5 — Intern Commission Sensitivity (varying attribution %)
A45: Intern attribution % | B45: Comm rate (Dashboard) | C45: Customers @ $1M | D45: Intern-sourced cust | E45: Intern attr ARR @ target | F45: Annual commission | G45: KnockIQ NET ARR | H45: Net % of $1M
A46: 0 | B46: =Dashboard!$B$14 -> 0.2 | C46: =ROUNDUP(Dashboard!$B$12/Dashboard!$B$20,0) -> 267 | D46: =ROUND(C46*A46,0) -> 0 | E46: =D46*Dashboard!$B$20 -> 0 | F46: =E46*B46 -> 0 | G46: =Dashboard!$B$12-F46 -> 1000000 | H46: =G46/Dashboard!$B$12 -> 1
A47: 0.25 | B47: =Dashboard!$B$14 -> 0.2 | C47: =ROUNDUP(Dashboard!$B$12/Dashboard!$B$20,0) -> 267 | D47: =ROUND(C47*A47,0) -> 67 | E47: =D47*Dashboard!$B$20 -> 251250 | F47: =E47*B47 -> 50250 | G47: =Dashboard!$B$12-F47 -> 949750 | H47: =G47/Dashboard!$B$12 -> 0.94975
A48: 0.5 | B48: =Dashboard!$B$14 -> 0.2 | C48: =ROUNDUP(Dashboard!$B$12/Dashboard!$B$20,0) -> 267 | D48: =ROUND(C48*A48,0) -> 134 | E48: =D48*Dashboard!$B$20 -> 502500 | F48: =E48*B48 -> 100500 | G48: =Dashboard!$B$12-F48 -> 899500 | H48: =G48/Dashboard!$B$12 -> 0.8995
...
